Watching for file changes with StatReloader
Homepage was accessed  hours!
C:\Users\Admin\Documents\python\ExpenseManager\user\views.py changed, reloading.
Watching for file changes with StatReloader
Homepage was accessed  hours!
C:\Users\Admin\Documents\python\ExpenseManager\user\views.py changed, reloading.
Watching for file changes with StatReloader
C:\Users\Admin\Documents\python\ExpenseManager\ExpenseManager\settings.py changed, reloading.
Watching for file changes with StatReloader
Homepage was accessed  hours!
C:\Users\Admin\Documents\python\ExpenseManager\ExpenseManager\settings.py changed, reloading.
Watching for file changes with StatReloader
Homepage was accessed  hours!
C:\Users\Admin\Documents\python\ExpenseManager\ExpenseManager\settings.py changed, reloading.
Watching for file changes with StatReloader
C:\Users\Admin\Documents\python\ExpenseManager\user\views.py changed, reloading.
Watching for file changes with StatReloader
Homepage was accessed  hours!
C:\Users\Admin\Documents\python\ExpenseManager\user\views.py changed, reloading.
Watching for file changes with StatReloader
Homepage was accessed  hours!
C:\Users\Admin\Documents\python\ExpenseManager\user\views.py changed, reloading.
Watching for file changes with StatReloader
Homepage was accessed  hours!
C:\Users\Admin\Documents\python\ExpenseManager\user\views.py changed, reloading.
Watching for file changes with StatReloader
C:\Users\Admin\Documents\python\ExpenseManager\ExpenseManager\settings.py changed, reloading.
Homepage was accessed  hours!
Homepage was accessed  hours!
Watching for file changes with StatReloader
C:\Users\Admin\Documents\python\ExpenseManager\ExpenseManager\settings.py changed, reloading.
Watching for file changes with StatReloader
Homepage was accessed  hours!
C:\Users\Admin\Documents\python\ExpenseManager\ExpenseManager\settings.py changed, reloading.
Watching for file changes with StatReloader
C:\Users\Admin\Documents\python\ExpenseManager\ExpenseManager\settings.py changed, reloading.
Watching for file changes with StatReloader
C:\Users\Admin\Documents\python\ExpenseManager\ExpenseManager\settings.py changed, reloading.
Watching for file changes with StatReloader
Homepage was accessed  hours!
Watching for file changes with StatReloader
Homepage was accessed  hours!
C:\Users\Admin\Documents\python\ExpenseManager\user\serializer.py changed, reloading.
Watching for file changes with StatReloader
Homepage was accessed  hours!
C:\Users\Admin\Documents\python\ExpenseManager\ledger\views.py changed, reloading.
Watching for file changes with StatReloader
C:\Users\Admin\Documents\python\ExpenseManager\ledger\views.py changed, reloading.
Watching for file changes with StatReloader
C:\Users\Admin\Documents\python\ExpenseManager\ledger\views.py changed, reloading.
Watching for file changes with StatReloader
C:\Users\Admin\Documents\python\ExpenseManager\ledger\views.py changed, reloading.
Watching for file changes with StatReloader
Homepage was accessed  hours!
C:\Users\Admin\Documents\python\ExpenseManager\ledger\models.py changed, reloading.
Watching for file changes with StatReloader
C:\Users\Admin\Documents\python\ExpenseManager\user\serializer.py changed, reloading.
Watching for file changes with StatReloader
Watching for file changes with StatReloader
Watching for file changes with StatReloader
Watching for file changes with StatReloader
C:\Users\Admin\Documents\python\ExpenseManager\ledger\views.py changed, reloading.
Watching for file changes with StatReloader
C:\Users\Admin\Documents\python\ExpenseManager\ledger\views.py changed, reloading.
Watching for file changes with StatReloader
Watching for file changes with StatReloader
C:\Users\Admin\Documents\python\ExpenseManager\ledger\views.py changed, reloading.
Watching for file changes with StatReloader
C:\Users\Admin\Documents\python\ExpenseManager\ledger\urls.py changed, reloading.
Watching for file changes with StatReloader
C:\Users\Admin\Documents\python\ExpenseManager\user\urls.py changed, reloading.
Watching for file changes with StatReloader
C:\Users\Admin\Documents\python\ExpenseManager\ledger\urls.py changed, reloading.
Watching for file changes with StatReloader
C:\Users\Admin\Documents\python\ExpenseManager\ledger\views.py changed, reloading.
Watching for file changes with StatReloader
Method Not Allowed: /user/2/ledger/2/split
Internal Server Error: /user/2/ledger/2/split
Traceback (most recent call last):
  File "C:\Python39\lib\site-packages\django\core\handlers\exception.py", line 55, in inner
    response = get_response(request)
  File "C:\Python39\lib\site-packages\django\core\handlers\base.py", line 197, in _get_response
    response = wrapped_callback(request, *callback_args, **callback_kwargs)
  File "C:\Python39\lib\site-packages\django\views\decorators\csrf.py", line 54, in wrapped_view
    return view_func(*args, **kwargs)
  File "C:\Python39\lib\site-packages\django\views\generic\base.py", line 84, in view
    return self.dispatch(request, *args, **kwargs)
  File "C:\Python39\lib\site-packages\rest_framework\views.py", line 509, in dispatch
    response = self.handle_exception(exc)
  File "C:\Python39\lib\site-packages\rest_framework\views.py", line 469, in handle_exception
    self.raise_uncaught_exception(exc)
  File "C:\Python39\lib\site-packages\rest_framework\views.py", line 480, in raise_uncaught_exception
    raise exc
  File "C:\Python39\lib\site-packages\rest_framework\views.py", line 506, in dispatch
    response = handler(request, *args, **kwargs)
  File "C:\Python39\lib\site-packages\rest_framework\decorators.py", line 50, in handler
    return func(*args, **kwargs)
  File "C:\Users\Admin\Documents\python\ExpenseManager\ledger\views.py", line 55, in split_expense
    ledger = Ledger.objects.get(user_id=user_id, pk=ledger_id)
  File "C:\Python39\lib\site-packages\django\db\models\manager.py", line 85, in manager_method
    return getattr(self.get_queryset(), name)(*args, **kwargs)
  File "C:\Python39\lib\site-packages\django\db\models\query.py", line 482, in get
    clone = self._chain() if self.query.combinator else self.filter(*args, **kwargs)
  File "C:\Python39\lib\site-packages\django\db\models\query.py", line 1071, in filter
    return self._filter_or_exclude(False, args, kwargs)
  File "C:\Python39\lib\site-packages\django\db\models\query.py", line 1089, in _filter_or_exclude
    clone._filter_or_exclude_inplace(negate, args, kwargs)
  File "C:\Python39\lib\site-packages\django\db\models\query.py", line 1096, in _filter_or_exclude_inplace
    self._query.add_q(Q(*args, **kwargs))
  File "C:\Python39\lib\site-packages\django\db\models\sql\query.py", line 1466, in add_q
    clause, _ = self._add_q(q_object, self.used_aliases)
  File "C:\Python39\lib\site-packages\django\db\models\sql\query.py", line 1496, in _add_q
    child_clause, needed_inner = self.build_filter(
  File "C:\Python39\lib\site-packages\django\db\models\sql\query.py", line 1342, in build_filter
    lookups, parts, reffed_expression = self.solve_lookup_type(arg)
  File "C:\Python39\lib\site-packages\django\db\models\sql\query.py", line 1156, in solve_lookup_type
    _, field, _, lookup_parts = self.names_to_path(lookup_splitted, self.get_meta())
  File "C:\Python39\lib\site-packages\django\db\models\sql\query.py", line 1640, in names_to_path
    raise FieldError(
django.core.exceptions.FieldError: Cannot resolve keyword 'user_id' into field. Choices are: amount, category, category_id, created_at, created_by, date, description, id, is_shared, name, shared_expense, total_amount, type, updated_at, updated_by, users
C:\Users\Admin\Documents\python\ExpenseManager\ledger\views.py changed, reloading.
Watching for file changes with StatReloader
Internal Server Error: /user/2/ledger/2/split
Traceback (most recent call last):
  File "C:\Python39\lib\site-packages\django\core\handlers\exception.py", line 55, in inner
    response = get_response(request)
  File "C:\Python39\lib\site-packages\django\core\handlers\base.py", line 197, in _get_response
    response = wrapped_callback(request, *callback_args, **callback_kwargs)
  File "C:\Python39\lib\site-packages\django\views\decorators\csrf.py", line 54, in wrapped_view
    return view_func(*args, **kwargs)
  File "C:\Python39\lib\site-packages\django\views\generic\base.py", line 84, in view
    return self.dispatch(request, *args, **kwargs)
  File "C:\Python39\lib\site-packages\rest_framework\views.py", line 509, in dispatch
    response = self.handle_exception(exc)
  File "C:\Python39\lib\site-packages\rest_framework\views.py", line 469, in handle_exception
    self.raise_uncaught_exception(exc)
  File "C:\Python39\lib\site-packages\rest_framework\views.py", line 480, in raise_uncaught_exception
    raise exc
  File "C:\Python39\lib\site-packages\rest_framework\views.py", line 506, in dispatch
    response = handler(request, *args, **kwargs)
  File "C:\Python39\lib\site-packages\rest_framework\decorators.py", line 50, in handler
    return func(*args, **kwargs)
  File "C:\Users\Admin\Documents\python\ExpenseManager\ledger\views.py", line 58, in split_expense
    ledger.users.extend(request.data['users'])
AttributeError: 'ManyRelatedManager' object has no attribute 'extend'
C:\Users\Admin\Documents\python\ExpenseManager\ledger\views.py changed, reloading.
Watching for file changes with StatReloader
Internal Server Error: /user/2/ledger/2/split
Traceback (most recent call last):
  File "C:\Python39\lib\site-packages\django\db\models\fields\__init__.py", line 1988, in get_prep_value
    return int(value)
TypeError: int() argument must be a string, a bytes-like object or a number, not 'list'

The above exception was the direct cause of the following exception:

Traceback (most recent call last):
  File "C:\Python39\lib\site-packages\django\core\handlers\exception.py", line 55, in inner
    response = get_response(request)
  File "C:\Python39\lib\site-packages\django\core\handlers\base.py", line 197, in _get_response
    response = wrapped_callback(request, *callback_args, **callback_kwargs)
  File "C:\Python39\lib\site-packages\django\views\decorators\csrf.py", line 54, in wrapped_view
    return view_func(*args, **kwargs)
  File "C:\Python39\lib\site-packages\django\views\generic\base.py", line 84, in view
    return self.dispatch(request, *args, **kwargs)
  File "C:\Python39\lib\site-packages\rest_framework\views.py", line 509, in dispatch
    response = self.handle_exception(exc)
  File "C:\Python39\lib\site-packages\rest_framework\views.py", line 469, in handle_exception
    self.raise_uncaught_exception(exc)
  File "C:\Python39\lib\site-packages\rest_framework\views.py", line 480, in raise_uncaught_exception
    raise exc
  File "C:\Python39\lib\site-packages\rest_framework\views.py", line 506, in dispatch
    response = handler(request, *args, **kwargs)
  File "C:\Python39\lib\site-packages\rest_framework\decorators.py", line 50, in handler
    return func(*args, **kwargs)
  File "C:\Users\Admin\Documents\python\ExpenseManager\ledger\views.py", line 58, in split_expense
    ledger.users.add(request.data['users'])
  File "C:\Python39\lib\site-packages\django\db\models\fields\related_descriptors.py", line 1048, in add
    self._add_items(
  File "C:\Python39\lib\site-packages\django\db\models\fields\related_descriptors.py", line 1263, in _add_items
    target_ids = self._get_target_ids(target_field_name, objs)
  File "C:\Python39\lib\site-packages\django\db\models\fields\related_descriptors.py", line 1197, in _get_target_ids
    target_ids.add(target_field.get_prep_value(obj))
  File "C:\Python39\lib\site-packages\django\db\models\fields\related.py", line 1132, in get_prep_value
    return self.target_field.get_prep_value(value)
  File "C:\Python39\lib\site-packages\django\db\models\fields\__init__.py", line 1990, in get_prep_value
    raise e.__class__(
TypeError: Field 'id' expected a number but got ['3'].
C:\Users\Admin\Documents\python\ExpenseManager\ledger\views.py changed, reloading.
Watching for file changes with StatReloader
Internal Server Error: /user/2/ledger/2/split
Traceback (most recent call last):
  File "C:\Python39\lib\site-packages\django\core\handlers\exception.py", line 55, in inner
    response = get_response(request)
  File "C:\Python39\lib\site-packages\django\core\handlers\base.py", line 197, in _get_response
    response = wrapped_callback(request, *callback_args, **callback_kwargs)
  File "C:\Python39\lib\site-packages\django\views\decorators\csrf.py", line 54, in wrapped_view
    return view_func(*args, **kwargs)
  File "C:\Python39\lib\site-packages\django\views\generic\base.py", line 84, in view
    return self.dispatch(request, *args, **kwargs)
  File "C:\Python39\lib\site-packages\rest_framework\views.py", line 509, in dispatch
    response = self.handle_exception(exc)
  File "C:\Python39\lib\site-packages\rest_framework\views.py", line 469, in handle_exception
    self.raise_uncaught_exception(exc)
  File "C:\Python39\lib\site-packages\rest_framework\views.py", line 480, in raise_uncaught_exception
    raise exc
  File "C:\Python39\lib\site-packages\rest_framework\views.py", line 506, in dispatch
    response = handler(request, *args, **kwargs)
  File "C:\Python39\lib\site-packages\rest_framework\decorators.py", line 50, in handler
    return func(*args, **kwargs)
  File "C:\Users\Admin\Documents\python\ExpenseManager\ledger\views.py", line 60, in split_expense
    ledger.amount = ledger.total_amount / len(ledger.users)
TypeError: object of type 'ManyRelatedManager' has no len()
C:\Users\Admin\Documents\python\ExpenseManager\ledger\views.py changed, reloading.
Watching for file changes with StatReloader
Internal Server Error: /user/2/ledger/2/split
Traceback (most recent call last):
  File "C:\Python39\lib\site-packages\django\core\handlers\exception.py", line 55, in inner
    response = get_response(request)
  File "C:\Python39\lib\site-packages\django\core\handlers\base.py", line 197, in _get_response
    response = wrapped_callback(request, *callback_args, **callback_kwargs)
  File "C:\Python39\lib\site-packages\django\views\decorators\csrf.py", line 54, in wrapped_view
    return view_func(*args, **kwargs)
  File "C:\Python39\lib\site-packages\django\views\generic\base.py", line 84, in view
    return self.dispatch(request, *args, **kwargs)
  File "C:\Python39\lib\site-packages\rest_framework\views.py", line 509, in dispatch
    response = self.handle_exception(exc)
  File "C:\Python39\lib\site-packages\rest_framework\views.py", line 469, in handle_exception
    self.raise_uncaught_exception(exc)
  File "C:\Python39\lib\site-packages\rest_framework\views.py", line 480, in raise_uncaught_exception
    raise exc
  File "C:\Python39\lib\site-packages\rest_framework\views.py", line 506, in dispatch
    response = handler(request, *args, **kwargs)
  File "C:\Python39\lib\site-packages\rest_framework\decorators.py", line 50, in handler
    return func(*args, **kwargs)
  File "C:\Users\Admin\Documents\python\ExpenseManager\ledger\views.py", line 61, in split_expense
    ledger.amount = ledger.total_amount / len(ledger.users)
TypeError: object of type 'ManyRelatedManager' has no len()
C:\Users\Admin\Documents\python\ExpenseManager\ledger\views.py changed, reloading.
Watching for file changes with StatReloader
Internal Server Error: /user/2/ledger/2/split
Traceback (most recent call last):
  File "C:\Python39\lib\site-packages\django\core\handlers\exception.py", line 55, in inner
    response = get_response(request)
  File "C:\Python39\lib\site-packages\django\core\handlers\base.py", line 197, in _get_response
    response = wrapped_callback(request, *callback_args, **callback_kwargs)
  File "C:\Python39\lib\site-packages\django\views\decorators\csrf.py", line 54, in wrapped_view
    return view_func(*args, **kwargs)
  File "C:\Python39\lib\site-packages\django\views\generic\base.py", line 84, in view
    return self.dispatch(request, *args, **kwargs)
  File "C:\Python39\lib\site-packages\rest_framework\views.py", line 509, in dispatch
    response = self.handle_exception(exc)
  File "C:\Python39\lib\site-packages\rest_framework\views.py", line 469, in handle_exception
    self.raise_uncaught_exception(exc)
  File "C:\Python39\lib\site-packages\rest_framework\views.py", line 480, in raise_uncaught_exception
    raise exc
  File "C:\Python39\lib\site-packages\rest_framework\views.py", line 506, in dispatch
    response = handler(request, *args, **kwargs)
  File "C:\Python39\lib\site-packages\rest_framework\decorators.py", line 50, in handler
    return func(*args, **kwargs)
  File "C:\Users\Admin\Documents\python\ExpenseManager\ledger\views.py", line 62, in split_expense
    ledger.amount = ledger.total_amount / len(ledger.users)
TypeError: object of type 'ManyRelatedManager' has no len()
C:\Users\Admin\Documents\python\ExpenseManager\ledger\views.py changed, reloading.
Watching for file changes with StatReloader
Internal Server Error: /user/2/ledger/2/split
Traceback (most recent call last):
  File "C:\Python39\lib\site-packages\django\core\handlers\exception.py", line 55, in inner
    response = get_response(request)
  File "C:\Python39\lib\site-packages\django\core\handlers\base.py", line 197, in _get_response
    response = wrapped_callback(request, *callback_args, **callback_kwargs)
  File "C:\Python39\lib\site-packages\django\views\decorators\csrf.py", line 54, in wrapped_view
    return view_func(*args, **kwargs)
  File "C:\Python39\lib\site-packages\django\views\generic\base.py", line 84, in view
    return self.dispatch(request, *args, **kwargs)
  File "C:\Python39\lib\site-packages\rest_framework\views.py", line 509, in dispatch
    response = self.handle_exception(exc)
  File "C:\Python39\lib\site-packages\rest_framework\views.py", line 469, in handle_exception
    self.raise_uncaught_exception(exc)
  File "C:\Python39\lib\site-packages\rest_framework\views.py", line 480, in raise_uncaught_exception
    raise exc
  File "C:\Python39\lib\site-packages\rest_framework\views.py", line 506, in dispatch
    response = handler(request, *args, **kwargs)
  File "C:\Python39\lib\site-packages\rest_framework\decorators.py", line 50, in handler
    return func(*args, **kwargs)
  File "C:\Users\Admin\Documents\python\ExpenseManager\ledger\views.py", line 61, in split_expense
    for user in users:
TypeError: 'ManyRelatedManager' object is not iterable
C:\Users\Admin\Documents\python\ExpenseManager\ledger\views.py changed, reloading.
Watching for file changes with StatReloader
Internal Server Error: /user/2/ledger/2/split
Traceback (most recent call last):
  File "C:\Python39\lib\site-packages\django\core\handlers\exception.py", line 55, in inner
    response = get_response(request)
  File "C:\Python39\lib\site-packages\django\core\handlers\base.py", line 197, in _get_response
    response = wrapped_callback(request, *callback_args, **callback_kwargs)
  File "C:\Python39\lib\site-packages\django\views\decorators\csrf.py", line 54, in wrapped_view
    return view_func(*args, **kwargs)
  File "C:\Python39\lib\site-packages\django\views\generic\base.py", line 84, in view
    return self.dispatch(request, *args, **kwargs)
  File "C:\Python39\lib\site-packages\rest_framework\views.py", line 509, in dispatch
    response = self.handle_exception(exc)
  File "C:\Python39\lib\site-packages\rest_framework\views.py", line 469, in handle_exception
    self.raise_uncaught_exception(exc)
  File "C:\Python39\lib\site-packages\rest_framework\views.py", line 480, in raise_uncaught_exception
    raise exc
  File "C:\Python39\lib\site-packages\rest_framework\views.py", line 506, in dispatch
    response = handler(request, *args, **kwargs)
  File "C:\Python39\lib\site-packages\rest_framework\decorators.py", line 50, in handler
    return func(*args, **kwargs)
  File "C:\Users\Admin\Documents\python\ExpenseManager\ledger\views.py", line 57, in split_expense
    print(ledger.users)
AttributeError: 'LedgerSerializer' object has no attribute 'users'
C:\Users\Admin\Documents\python\ExpenseManager\ledger\views.py changed, reloading.
Watching for file changes with StatReloader
Internal Server Error: /user/2/ledger/2/split
Traceback (most recent call last):
  File "C:\Python39\lib\site-packages\django\core\handlers\exception.py", line 55, in inner
    response = get_response(request)
  File "C:\Python39\lib\site-packages\django\core\handlers\base.py", line 197, in _get_response
    response = wrapped_callback(request, *callback_args, **callback_kwargs)
  File "C:\Python39\lib\site-packages\django\views\decorators\csrf.py", line 54, in wrapped_view
    return view_func(*args, **kwargs)
  File "C:\Python39\lib\site-packages\django\views\generic\base.py", line 84, in view
    return self.dispatch(request, *args, **kwargs)
  File "C:\Python39\lib\site-packages\rest_framework\views.py", line 509, in dispatch
    response = self.handle_exception(exc)
  File "C:\Python39\lib\site-packages\rest_framework\views.py", line 469, in handle_exception
    self.raise_uncaught_exception(exc)
  File "C:\Python39\lib\site-packages\rest_framework\views.py", line 480, in raise_uncaught_exception
    raise exc
  File "C:\Python39\lib\site-packages\rest_framework\views.py", line 506, in dispatch
    response = handler(request, *args, **kwargs)
  File "C:\Python39\lib\site-packages\rest_framework\decorators.py", line 50, in handler
    return func(*args, **kwargs)
  File "C:\Users\Admin\Documents\python\ExpenseManager\ledger\views.py", line 57, in split_expense
    print(ledger.data.users)
AttributeError: 'ReturnDict' object has no attribute 'users'
Internal Server Error: /user/2/ledger/2/
Traceback (most recent call last):
  File "C:\Python39\lib\site-packages\django\core\handlers\exception.py", line 55, in inner
    response = get_response(request)
  File "C:\Python39\lib\site-packages\django\core\handlers\base.py", line 197, in _get_response
    response = wrapped_callback(request, *callback_args, **callback_kwargs)
  File "C:\Python39\lib\site-packages\django\views\decorators\csrf.py", line 54, in wrapped_view
    return view_func(*args, **kwargs)
  File "C:\Python39\lib\site-packages\rest_framework\viewsets.py", line 125, in view
    return self.dispatch(request, *args, **kwargs)
  File "C:\Python39\lib\site-packages\rest_framework\views.py", line 509, in dispatch
    response = self.handle_exception(exc)
  File "C:\Python39\lib\site-packages\rest_framework\views.py", line 469, in handle_exception
    self.raise_uncaught_exception(exc)
  File "C:\Python39\lib\site-packages\rest_framework\views.py", line 480, in raise_uncaught_exception
    raise exc
  File "C:\Python39\lib\site-packages\rest_framework\views.py", line 506, in dispatch
    response = handler(request, *args, **kwargs)
  File "C:\Users\Admin\Documents\python\ExpenseManager\ledger\views.py", line 43, in retrieve
    ledger = Ledger.objects.get(user_id=user_id, pk=ledger_id)
  File "C:\Python39\lib\site-packages\django\db\models\manager.py", line 85, in manager_method
    return getattr(self.get_queryset(), name)(*args, **kwargs)
  File "C:\Python39\lib\site-packages\django\db\models\query.py", line 482, in get
    clone = self._chain() if self.query.combinator else self.filter(*args, **kwargs)
  File "C:\Python39\lib\site-packages\django\db\models\query.py", line 1071, in filter
    return self._filter_or_exclude(False, args, kwargs)
  File "C:\Python39\lib\site-packages\django\db\models\query.py", line 1089, in _filter_or_exclude
    clone._filter_or_exclude_inplace(negate, args, kwargs)
  File "C:\Python39\lib\site-packages\django\db\models\query.py", line 1096, in _filter_or_exclude_inplace
    self._query.add_q(Q(*args, **kwargs))
  File "C:\Python39\lib\site-packages\django\db\models\sql\query.py", line 1466, in add_q
    clause, _ = self._add_q(q_object, self.used_aliases)
  File "C:\Python39\lib\site-packages\django\db\models\sql\query.py", line 1496, in _add_q
    child_clause, needed_inner = self.build_filter(
  File "C:\Python39\lib\site-packages\django\db\models\sql\query.py", line 1342, in build_filter
    lookups, parts, reffed_expression = self.solve_lookup_type(arg)
  File "C:\Python39\lib\site-packages\django\db\models\sql\query.py", line 1156, in solve_lookup_type
    _, field, _, lookup_parts = self.names_to_path(lookup_splitted, self.get_meta())
  File "C:\Python39\lib\site-packages\django\db\models\sql\query.py", line 1640, in names_to_path
    raise FieldError(
django.core.exceptions.FieldError: Cannot resolve keyword 'user_id' into field. Choices are: amount, category, category_id, created_at, created_by, date, description, id, is_shared, name, shared_expense, total_amount, type, updated_at, updated_by, users
Internal Server Error: /user/2/ledger/2/
Traceback (most recent call last):
  File "C:\Python39\lib\site-packages\django\core\handlers\exception.py", line 55, in inner
    response = get_response(request)
  File "C:\Python39\lib\site-packages\django\core\handlers\base.py", line 197, in _get_response
    response = wrapped_callback(request, *callback_args, **callback_kwargs)
  File "C:\Python39\lib\site-packages\django\views\decorators\csrf.py", line 54, in wrapped_view
    return view_func(*args, **kwargs)
  File "C:\Python39\lib\site-packages\rest_framework\viewsets.py", line 125, in view
    return self.dispatch(request, *args, **kwargs)
  File "C:\Python39\lib\site-packages\rest_framework\views.py", line 509, in dispatch
    response = self.handle_exception(exc)
  File "C:\Python39\lib\site-packages\rest_framework\views.py", line 469, in handle_exception
    self.raise_uncaught_exception(exc)
  File "C:\Python39\lib\site-packages\rest_framework\views.py", line 480, in raise_uncaught_exception
    raise exc
  File "C:\Python39\lib\site-packages\rest_framework\views.py", line 506, in dispatch
    response = handler(request, *args, **kwargs)
  File "C:\Users\Admin\Documents\python\ExpenseManager\ledger\views.py", line 43, in retrieve
    ledger = Ledger.objects.get(user_id=user_id, pk=ledger_id)
  File "C:\Python39\lib\site-packages\django\db\models\manager.py", line 85, in manager_method
    return getattr(self.get_queryset(), name)(*args, **kwargs)
  File "C:\Python39\lib\site-packages\django\db\models\query.py", line 482, in get
    clone = self._chain() if self.query.combinator else self.filter(*args, **kwargs)
  File "C:\Python39\lib\site-packages\django\db\models\query.py", line 1071, in filter
    return self._filter_or_exclude(False, args, kwargs)
  File "C:\Python39\lib\site-packages\django\db\models\query.py", line 1089, in _filter_or_exclude
    clone._filter_or_exclude_inplace(negate, args, kwargs)
  File "C:\Python39\lib\site-packages\django\db\models\query.py", line 1096, in _filter_or_exclude_inplace
    self._query.add_q(Q(*args, **kwargs))
  File "C:\Python39\lib\site-packages\django\db\models\sql\query.py", line 1466, in add_q
    clause, _ = self._add_q(q_object, self.used_aliases)
  File "C:\Python39\lib\site-packages\django\db\models\sql\query.py", line 1496, in _add_q
    child_clause, needed_inner = self.build_filter(
  File "C:\Python39\lib\site-packages\django\db\models\sql\query.py", line 1342, in build_filter
    lookups, parts, reffed_expression = self.solve_lookup_type(arg)
  File "C:\Python39\lib\site-packages\django\db\models\sql\query.py", line 1156, in solve_lookup_type
    _, field, _, lookup_parts = self.names_to_path(lookup_splitted, self.get_meta())
  File "C:\Python39\lib\site-packages\django\db\models\sql\query.py", line 1640, in names_to_path
    raise FieldError(
django.core.exceptions.FieldError: Cannot resolve keyword 'user_id' into field. Choices are: amount, category, category_id, created_at, created_by, date, description, id, is_shared, name, shared_expense, total_amount, type, updated_at, updated_by, users
C:\Users\Admin\Documents\python\ExpenseManager\ledger\views.py changed, reloading.
Watching for file changes with StatReloader
C:\Users\Admin\Documents\python\ExpenseManager\ledger\views.py changed, reloading.
Watching for file changes with StatReloader
Internal Server Error: /user/2/ledger/2/split
Traceback (most recent call last):
  File "C:\Python39\lib\site-packages\django\core\handlers\exception.py", line 55, in inner
    response = get_response(request)
  File "C:\Python39\lib\site-packages\django\core\handlers\base.py", line 197, in _get_response
    response = wrapped_callback(request, *callback_args, **callback_kwargs)
  File "C:\Python39\lib\site-packages\django\views\decorators\csrf.py", line 54, in wrapped_view
    return view_func(*args, **kwargs)
  File "C:\Python39\lib\site-packages\django\views\generic\base.py", line 84, in view
    return self.dispatch(request, *args, **kwargs)
  File "C:\Python39\lib\site-packages\rest_framework\views.py", line 509, in dispatch
    response = self.handle_exception(exc)
  File "C:\Python39\lib\site-packages\rest_framework\views.py", line 469, in handle_exception
    self.raise_uncaught_exception(exc)
  File "C:\Python39\lib\site-packages\rest_framework\views.py", line 480, in raise_uncaught_exception
    raise exc
  File "C:\Python39\lib\site-packages\rest_framework\views.py", line 506, in dispatch
    response = handler(request, *args, **kwargs)
  File "C:\Python39\lib\site-packages\rest_framework\decorators.py", line 50, in handler
    return func(*args, **kwargs)
  File "C:\Users\Admin\Documents\python\ExpenseManager\ledger\views.py", line 58, in split_expense
    if not ledger.is_shared:
AttributeError: 'LedgerSerializer' object has no attribute 'is_shared'
C:\Users\Admin\Documents\python\ExpenseManager\ledger\views.py changed, reloading.
Watching for file changes with StatReloader
C:\Users\Admin\Documents\python\ExpenseManager\ledger\views.py changed, reloading.
Watching for file changes with StatReloader
Internal Server Error: /user/2/ledger/1/split
Traceback (most recent call last):
  File "C:\Python39\lib\site-packages\django\core\handlers\exception.py", line 55, in inner
    response = get_response(request)
  File "C:\Python39\lib\site-packages\django\core\handlers\base.py", line 197, in _get_response
    response = wrapped_callback(request, *callback_args, **callback_kwargs)
  File "C:\Python39\lib\site-packages\django\views\decorators\csrf.py", line 54, in wrapped_view
    return view_func(*args, **kwargs)
  File "C:\Python39\lib\site-packages\django\views\generic\base.py", line 84, in view
    return self.dispatch(request, *args, **kwargs)
  File "C:\Python39\lib\site-packages\rest_framework\views.py", line 509, in dispatch
    response = self.handle_exception(exc)
  File "C:\Python39\lib\site-packages\rest_framework\views.py", line 469, in handle_exception
    self.raise_uncaught_exception(exc)
  File "C:\Python39\lib\site-packages\rest_framework\views.py", line 480, in raise_uncaught_exception
    raise exc
  File "C:\Python39\lib\site-packages\rest_framework\views.py", line 506, in dispatch
    response = handler(request, *args, **kwargs)
  File "C:\Python39\lib\site-packages\rest_framework\decorators.py", line 50, in handler
    return func(*args, **kwargs)
  File "C:\Users\Admin\Documents\python\ExpenseManager\ledger\views.py", line 61, in split_expense
    request['amount'] = ledger.total_amount / len(request.data['users'])
TypeError: 'Request' object does not support item assignment
Homepage was accessed  hours!
C:\Users\Admin\Documents\python\ExpenseManager\ledger\views.py changed, reloading.
Watching for file changes with StatReloader
Internal Server Error: /user/2/ledger/1/split
Traceback (most recent call last):
  File "C:\Python39\lib\site-packages\django\core\handlers\exception.py", line 55, in inner
    response = get_response(request)
  File "C:\Python39\lib\site-packages\django\core\handlers\base.py", line 197, in _get_response
    response = wrapped_callback(request, *callback_args, **callback_kwargs)
  File "C:\Python39\lib\site-packages\django\views\decorators\csrf.py", line 54, in wrapped_view
    return view_func(*args, **kwargs)
  File "C:\Python39\lib\site-packages\django\views\generic\base.py", line 84, in view
    return self.dispatch(request, *args, **kwargs)
  File "C:\Python39\lib\site-packages\rest_framework\views.py", line 509, in dispatch
    response = self.handle_exception(exc)
  File "C:\Python39\lib\site-packages\rest_framework\views.py", line 469, in handle_exception
    self.raise_uncaught_exception(exc)
  File "C:\Python39\lib\site-packages\rest_framework\views.py", line 480, in raise_uncaught_exception
    raise exc
  File "C:\Python39\lib\site-packages\rest_framework\views.py", line 506, in dispatch
    response = handler(request, *args, **kwargs)
  File "C:\Python39\lib\site-packages\rest_framework\decorators.py", line 50, in handler
    return func(*args, **kwargs)
  File "C:\Users\Admin\Documents\python\ExpenseManager\ledger\views.py", line 61, in split_expense
    request['amount'] = ledger.total_amount/len(request.data['users'])
TypeError: 'Request' object does not support item assignment
C:\Users\Admin\Documents\python\ExpenseManager\ledger\views.py changed, reloading.
Watching for file changes with StatReloader
Internal Server Error: /user/2/ledger/1/split
Traceback (most recent call last):
  File "C:\Python39\lib\site-packages\django\core\handlers\exception.py", line 55, in inner
    response = get_response(request)
  File "C:\Python39\lib\site-packages\django\core\handlers\base.py", line 197, in _get_response
    response = wrapped_callback(request, *callback_args, **callback_kwargs)
  File "C:\Python39\lib\site-packages\django\views\decorators\csrf.py", line 54, in wrapped_view
    return view_func(*args, **kwargs)
  File "C:\Python39\lib\site-packages\django\views\generic\base.py", line 84, in view
    return self.dispatch(request, *args, **kwargs)
  File "C:\Python39\lib\site-packages\rest_framework\views.py", line 509, in dispatch
    response = self.handle_exception(exc)
  File "C:\Python39\lib\site-packages\rest_framework\views.py", line 469, in handle_exception
    self.raise_uncaught_exception(exc)
  File "C:\Python39\lib\site-packages\rest_framework\views.py", line 480, in raise_uncaught_exception
    raise exc
  File "C:\Python39\lib\site-packages\rest_framework\views.py", line 506, in dispatch
    response = handler(request, *args, **kwargs)
  File "C:\Python39\lib\site-packages\rest_framework\decorators.py", line 50, in handler
    return func(*args, **kwargs)
  File "C:\Users\Admin\Documents\python\ExpenseManager\ledger\views.py", line 62, in split_expense
    request['amount'] = amount
TypeError: 'Request' object does not support item assignment
C:\Users\Admin\Documents\python\ExpenseManager\ledger\views.py changed, reloading.
Watching for file changes with StatReloader
Internal Server Error: /user/2/ledger/1/split
Traceback (most recent call last):
  File "C:\Python39\lib\site-packages\django\core\handlers\exception.py", line 55, in inner
    response = get_response(request)
  File "C:\Python39\lib\site-packages\django\core\handlers\base.py", line 197, in _get_response
    response = wrapped_callback(request, *callback_args, **callback_kwargs)
  File "C:\Python39\lib\site-packages\django\views\decorators\csrf.py", line 54, in wrapped_view
    return view_func(*args, **kwargs)
  File "C:\Python39\lib\site-packages\django\views\generic\base.py", line 84, in view
    return self.dispatch(request, *args, **kwargs)
  File "C:\Python39\lib\site-packages\rest_framework\views.py", line 509, in dispatch
    response = self.handle_exception(exc)
  File "C:\Python39\lib\site-packages\rest_framework\views.py", line 469, in handle_exception
    self.raise_uncaught_exception(exc)
  File "C:\Python39\lib\site-packages\rest_framework\views.py", line 480, in raise_uncaught_exception
    raise exc
  File "C:\Python39\lib\site-packages\rest_framework\views.py", line 506, in dispatch
    response = handler(request, *args, **kwargs)
  File "C:\Python39\lib\site-packages\rest_framework\decorators.py", line 50, in handler
    return func(*args, **kwargs)
  File "C:\Users\Admin\Documents\python\ExpenseManager\ledger\views.py", line 65, in split_expense
    return Response(ledger)
  File "C:\Python39\lib\site-packages\rest_framework\response.py", line 38, in __init__
    raise AssertionError(msg)
AssertionError: You passed a Serializer instance as data, but probably meant to pass serialized `.data` or `.error`. representation.
C:\Users\Admin\Documents\python\ExpenseManager\ledger\views.py changed, reloading.
Watching for file changes with StatReloader
Internal Server Error: /user/1/ledger/1/
Traceback (most recent call last):
  File "C:\Python39\lib\site-packages\django\db\backends\utils.py", line 89, in _execute
    return self.cursor.execute(sql, params)
  File "C:\Python39\lib\site-packages\django\db\backends\mysql\base.py", line 75, in execute
    return self.cursor.execute(query, args)
  File "C:\Python39\lib\site-packages\MySQLdb\cursors.py", line 206, in execute
    res = self._query(query)
  File "C:\Python39\lib\site-packages\MySQLdb\cursors.py", line 319, in _query
    db.query(q)
  File "C:\Python39\lib\site-packages\MySQLdb\connections.py", line 254, in query
    _mysql.connection.query(self, query)
MySQLdb._exceptions.ProgrammingError: (1146, "Table 'expensemanager.shared_expense_sharedexpense' doesn't exist")

The above exception was the direct cause of the following exception:

Traceback (most recent call last):
  File "C:\Python39\lib\site-packages\django\core\handlers\exception.py", line 55, in inner
    response = get_response(request)
  File "C:\Python39\lib\site-packages\django\core\handlers\base.py", line 197, in _get_response
    response = wrapped_callback(request, *callback_args, **callback_kwargs)
  File "C:\Python39\lib\site-packages\django\views\decorators\csrf.py", line 54, in wrapped_view
    return view_func(*args, **kwargs)
  File "C:\Python39\lib\site-packages\rest_framework\viewsets.py", line 125, in view
    return self.dispatch(request, *args, **kwargs)
  File "C:\Python39\lib\site-packages\rest_framework\views.py", line 509, in dispatch
    response = self.handle_exception(exc)
  File "C:\Python39\lib\site-packages\rest_framework\views.py", line 469, in handle_exception
    self.raise_uncaught_exception(exc)
  File "C:\Python39\lib\site-packages\rest_framework\views.py", line 480, in raise_uncaught_exception
    raise exc
  File "C:\Python39\lib\site-packages\rest_framework\views.py", line 506, in dispatch
    response = handler(request, *args, **kwargs)
  File "C:\Python39\lib\site-packages\rest_framework\mixins.py", line 91, in destroy
    self.perform_destroy(instance)
  File "C:\Python39\lib\site-packages\rest_framework\mixins.py", line 95, in perform_destroy
    instance.delete()
  File "C:\Python39\lib\site-packages\django\db\models\base.py", line 1093, in delete
    collector.collect([self], keep_parents=keep_parents)
  File "C:\Python39\lib\site-packages\django\db\models\deletion.py", line 341, in collect
    if sub_objs:
  File "C:\Python39\lib\site-packages\django\db\models\query.py", line 324, in __bool__
    self._fetch_all()
  File "C:\Python39\lib\site-packages\django\db\models\query.py", line 1507, in _fetch_all
    self._result_cache = list(self._iterable_class(self))
  File "C:\Python39\lib\site-packages\django\db\models\query.py", line 57, in __iter__
    results = compiler.execute_sql(
  File "C:\Python39\lib\site-packages\django\db\models\sql\compiler.py", line 1361, in execute_sql
    cursor.execute(sql, params)
  File "C:\Python39\lib\site-packages\django\db\backends\utils.py", line 103, in execute
    return super().execute(sql, params)
  File "C:\Python39\lib\site-packages\django\db\backends\utils.py", line 67, in execute
    return self._execute_with_wrappers(
  File "C:\Python39\lib\site-packages\django\db\backends\utils.py", line 80, in _execute_with_wrappers
    return executor(sql, params, many, context)
  File "C:\Python39\lib\site-packages\django\db\backends\utils.py", line 89, in _execute
    return self.cursor.execute(sql, params)
  File "C:\Python39\lib\site-packages\django\db\utils.py", line 91, in __exit__
    raise dj_exc_value.with_traceback(traceback) from exc_value
  File "C:\Python39\lib\site-packages\django\db\backends\utils.py", line 89, in _execute
    return self.cursor.execute(sql, params)
  File "C:\Python39\lib\site-packages\django\db\backends\mysql\base.py", line 75, in execute
    return self.cursor.execute(query, args)
  File "C:\Python39\lib\site-packages\MySQLdb\cursors.py", line 206, in execute
    res = self._query(query)
  File "C:\Python39\lib\site-packages\MySQLdb\cursors.py", line 319, in _query
    db.query(q)
  File "C:\Python39\lib\site-packages\MySQLdb\connections.py", line 254, in query
    _mysql.connection.query(self, query)
django.db.utils.ProgrammingError: (1146, "Table 'expensemanager.shared_expense_sharedexpense' doesn't exist")
C:\Users\Admin\Documents\python\ExpenseManager\ExpenseManager\settings.py changed, reloading.
Watching for file changes with StatReloader
C:\Users\Admin\Documents\python\ExpenseManager\user\serializer.py changed, reloading.
Watching for file changes with StatReloader
C:\Users\Admin\Documents\python\ExpenseManager\ledger\views.py changed, reloading.
Watching for file changes with StatReloader
Internal Server Error: /user/2/ledger/4/split
Traceback (most recent call last):
  File "C:\Python39\lib\site-packages\django\core\handlers\exception.py", line 55, in inner
    response = get_response(request)
  File "C:\Python39\lib\site-packages\django\core\handlers\base.py", line 197, in _get_response
    response = wrapped_callback(request, *callback_args, **callback_kwargs)
  File "C:\Python39\lib\site-packages\django\views\decorators\csrf.py", line 54, in wrapped_view
    return view_func(*args, **kwargs)
  File "C:\Python39\lib\site-packages\django\views\generic\base.py", line 84, in view
    return self.dispatch(request, *args, **kwargs)
  File "C:\Python39\lib\site-packages\rest_framework\views.py", line 509, in dispatch
    response = self.handle_exception(exc)
  File "C:\Python39\lib\site-packages\rest_framework\views.py", line 469, in handle_exception
    self.raise_uncaught_exception(exc)
  File "C:\Python39\lib\site-packages\rest_framework\views.py", line 480, in raise_uncaught_exception
    raise exc
  File "C:\Python39\lib\site-packages\rest_framework\views.py", line 506, in dispatch
    response = handler(request, *args, **kwargs)
  File "C:\Python39\lib\site-packages\rest_framework\decorators.py", line 50, in handler
    return func(*args, **kwargs)
  File "C:\Users\Admin\Documents\python\ExpenseManager\ledger\views.py", line 55, in split_expense
    ledger = Ledger.objects.get(pk=ledger_id, type='expense')
  File "C:\Python39\lib\site-packages\django\db\models\manager.py", line 85, in manager_method
    return getattr(self.get_queryset(), name)(*args, **kwargs)
  File "C:\Python39\lib\site-packages\django\db\models\query.py", line 496, in get
    raise self.model.DoesNotExist(
ledger.models.Ledger.DoesNotExist: Ledger matching query does not exist.
C:\Users\Admin\Documents\python\ExpenseManager\ledger\views.py changed, reloading.
Watching for file changes with StatReloader
Internal Server Error: /user/2/ledger/4/split
Traceback (most recent call last):
  File "C:\Python39\lib\site-packages\django\core\handlers\exception.py", line 55, in inner
    response = get_response(request)
  File "C:\Python39\lib\site-packages\django\core\handlers\base.py", line 197, in _get_response
    response = wrapped_callback(request, *callback_args, **callback_kwargs)
  File "C:\Python39\lib\site-packages\django\views\decorators\csrf.py", line 54, in wrapped_view
    return view_func(*args, **kwargs)
  File "C:\Python39\lib\site-packages\django\views\generic\base.py", line 84, in view
    return self.dispatch(request, *args, **kwargs)
  File "C:\Python39\lib\site-packages\rest_framework\views.py", line 509, in dispatch
    response = self.handle_exception(exc)
  File "C:\Python39\lib\site-packages\rest_framework\views.py", line 469, in handle_exception
    self.raise_uncaught_exception(exc)
  File "C:\Python39\lib\site-packages\rest_framework\views.py", line 480, in raise_uncaught_exception
    raise exc
  File "C:\Python39\lib\site-packages\rest_framework\views.py", line 506, in dispatch
    response = handler(request, *args, **kwargs)
  File "C:\Python39\lib\site-packages\rest_framework\decorators.py", line 50, in handler
    return func(*args, **kwargs)
  File "C:\Users\Admin\Documents\python\ExpenseManager\ledger\views.py", line 55, in split_expense
    ledger = Ledger.objects.get(pk=ledger_id, type='Expense')
  File "C:\Python39\lib\site-packages\django\db\models\manager.py", line 85, in manager_method
    return getattr(self.get_queryset(), name)(*args, **kwargs)
  File "C:\Python39\lib\site-packages\django\db\models\query.py", line 496, in get
    raise self.model.DoesNotExist(
ledger.models.Ledger.DoesNotExist: Ledger matching query does not exist.
C:\Users\Admin\Documents\python\ExpenseManager\ledger\views.py changed, reloading.
Watching for file changes with StatReloader
Internal Server Error: /user/2/ledger/4/split
Traceback (most recent call last):
  File "C:\Python39\lib\site-packages\django\core\handlers\exception.py", line 55, in inner
    response = get_response(request)
  File "C:\Python39\lib\site-packages\django\core\handlers\base.py", line 197, in _get_response
    response = wrapped_callback(request, *callback_args, **callback_kwargs)
  File "C:\Python39\lib\site-packages\django\views\decorators\csrf.py", line 54, in wrapped_view
    return view_func(*args, **kwargs)
  File "C:\Python39\lib\site-packages\django\views\generic\base.py", line 84, in view
    return self.dispatch(request, *args, **kwargs)
  File "C:\Python39\lib\site-packages\rest_framework\views.py", line 509, in dispatch
    response = self.handle_exception(exc)
  File "C:\Python39\lib\site-packages\rest_framework\views.py", line 469, in handle_exception
    self.raise_uncaught_exception(exc)
  File "C:\Python39\lib\site-packages\rest_framework\views.py", line 480, in raise_uncaught_exception
    raise exc
  File "C:\Python39\lib\site-packages\rest_framework\views.py", line 506, in dispatch
    response = handler(request, *args, **kwargs)
  File "C:\Python39\lib\site-packages\rest_framework\decorators.py", line 50, in handler
    return func(*args, **kwargs)
  File "C:\Users\Admin\Documents\python\ExpenseManager\ledger\views.py", line 56, in split_expense
    if not ledger.is_shared:
AttributeError: 'QuerySet' object has no attribute 'is_shared'
C:\Users\Admin\Documents\python\ExpenseManager\ledger\views.py changed, reloading.
Watching for file changes with StatReloader
Internal Server Error: /user/2/ledger/4/split
Traceback (most recent call last):
  File "C:\Python39\lib\site-packages\django\core\handlers\exception.py", line 55, in inner
    response = get_response(request)
  File "C:\Python39\lib\site-packages\django\core\handlers\base.py", line 197, in _get_response
    response = wrapped_callback(request, *callback_args, **callback_kwargs)
  File "C:\Python39\lib\site-packages\django\views\decorators\csrf.py", line 54, in wrapped_view
    return view_func(*args, **kwargs)
  File "C:\Python39\lib\site-packages\django\views\generic\base.py", line 84, in view
    return self.dispatch(request, *args, **kwargs)
  File "C:\Python39\lib\site-packages\rest_framework\views.py", line 509, in dispatch
    response = self.handle_exception(exc)
  File "C:\Python39\lib\site-packages\rest_framework\views.py", line 469, in handle_exception
    self.raise_uncaught_exception(exc)
  File "C:\Python39\lib\site-packages\rest_framework\views.py", line 480, in raise_uncaught_exception
    raise exc
  File "C:\Python39\lib\site-packages\rest_framework\views.py", line 506, in dispatch
    response = handler(request, *args, **kwargs)
  File "C:\Python39\lib\site-packages\rest_framework\decorators.py", line 50, in handler
    return func(*args, **kwargs)
  File "C:\Users\Admin\Documents\python\ExpenseManager\ledger\views.py", line 57, in split_expense
    if not ledger.is_shared:
AttributeError: 'QuerySet' object has no attribute 'is_shared'
C:\Users\Admin\Documents\python\ExpenseManager\ledger\views.py changed, reloading.
Watching for file changes with StatReloader
Internal Server Error: /user/2/ledger/4/split
Traceback (most recent call last):
  File "C:\Python39\lib\site-packages\django\core\handlers\exception.py", line 55, in inner
    response = get_response(request)
  File "C:\Python39\lib\site-packages\django\core\handlers\base.py", line 197, in _get_response
    response = wrapped_callback(request, *callback_args, **callback_kwargs)
  File "C:\Python39\lib\site-packages\django\views\decorators\csrf.py", line 54, in wrapped_view
    return view_func(*args, **kwargs)
  File "C:\Python39\lib\site-packages\django\views\generic\base.py", line 84, in view
    return self.dispatch(request, *args, **kwargs)
  File "C:\Python39\lib\site-packages\rest_framework\views.py", line 509, in dispatch
    response = self.handle_exception(exc)
  File "C:\Python39\lib\site-packages\rest_framework\views.py", line 469, in handle_exception
    self.raise_uncaught_exception(exc)
  File "C:\Python39\lib\site-packages\rest_framework\views.py", line 480, in raise_uncaught_exception
    raise exc
  File "C:\Python39\lib\site-packages\rest_framework\views.py", line 506, in dispatch
    response = handler(request, *args, **kwargs)
  File "C:\Python39\lib\site-packages\rest_framework\decorators.py", line 50, in handler
    return func(*args, **kwargs)
  File "C:\Users\Admin\Documents\python\ExpenseManager\ledger\views.py", line 57, in split_expense
    if not ledger.is_shared:
AttributeError: 'QuerySet' object has no attribute 'is_shared'
C:\Users\Admin\Documents\python\ExpenseManager\ledger\views.py changed, reloading.
Watching for file changes with StatReloader
C:\Users\Admin\Documents\python\ExpenseManager\ledger\views.py changed, reloading.
Watching for file changes with StatReloader
C:\Users\Admin\Documents\python\ExpenseManager\ledger\views.py changed, reloading.
Watching for file changes with StatReloader
Watching for file changes with StatReloader
Watching for file changes with StatReloader
C:\Users\Admin\Documents\python\ExpenseManager\ExpenseManager\settings.py changed, reloading.
Watching for file changes with StatReloader
C:\Users\Admin\Documents\python\ExpenseManager\ExpenseManager\settings.py changed, reloading.
Watching for file changes with StatReloader
Watching for file changes with StatReloader
Watching for file changes with StatReloader
Get user method called.
Watching for file changes with StatReloader
Internal Server Error: /user/create
Traceback (most recent call last):
  File "C:\Python39\lib\site-packages\django\core\handlers\exception.py", line 55, in inner
    response = get_response(request)
  File "C:\Python39\lib\site-packages\django\core\handlers\base.py", line 197, in _get_response
    response = wrapped_callback(request, *callback_args, **callback_kwargs)
  File "C:\Python39\lib\site-packages\django\views\decorators\csrf.py", line 54, in wrapped_view
    return view_func(*args, **kwargs)
  File "C:\Python39\lib\site-packages\django\views\generic\base.py", line 84, in view
    return self.dispatch(request, *args, **kwargs)
  File "C:\Python39\lib\site-packages\rest_framework\views.py", line 511, in dispatch
    self.response = self.finalize_response(request, response, *args, **kwargs)
  File "C:\Python39\lib\site-packages\rest_framework\views.py", line 423, in finalize_response
    assert isinstance(response, HttpResponseBase), (
AssertionError: Expected a `Response`, `HttpResponse` or `HttpStreamingResponse` to be returned from the view, but received a `<class 'NoneType'>`
C:\Users\Admin\Documents\python\ExpenseManager\ExpenseManager\settings.py changed, reloading.
Watching for file changes with StatReloader
Internal Server Error: /user/create
Traceback (most recent call last):
  File "C:\Python39\lib\site-packages\django\core\handlers\exception.py", line 55, in inner
    response = get_response(request)
  File "C:\Python39\lib\site-packages\django\core\handlers\base.py", line 197, in _get_response
    response = wrapped_callback(request, *callback_args, **callback_kwargs)
  File "C:\Python39\lib\site-packages\django\views\decorators\csrf.py", line 54, in wrapped_view
    return view_func(*args, **kwargs)
  File "C:\Python39\lib\site-packages\django\views\generic\base.py", line 84, in view
    return self.dispatch(request, *args, **kwargs)
  File "C:\Python39\lib\site-packages\rest_framework\views.py", line 511, in dispatch
    self.response = self.finalize_response(request, response, *args, **kwargs)
  File "C:\Python39\lib\site-packages\rest_framework\views.py", line 423, in finalize_response
    assert isinstance(response, HttpResponseBase), (
AssertionError: Expected a `Response`, `HttpResponse` or `HttpStreamingResponse` to be returned from the view, but received a `<class 'NoneType'>`
Get user method called.
